Workbook

Sheet Содержание
D4: Финансовая модель
D6: =Ввод!M11 -> Строительства завода по производству винтовых свай
D8: Как работает модель
D10: Модель построена в логике ввод → расчёты → отчётность → результаты. Листы Отчётность и Результат формируются автоматически.
D12: Содержание
D14: Лист | F14: Блок | I14: Описание
D16: Ввод | F16: - | I16: Лист для ввода исходных данных. Содержит ключевые параметры проекта в разрезе блоков модели (выручка, затраты, персонал, инвестиции, налоги, финансирование).
D17: Расчет | F17: Выручка | I17: Прогноз выручки: план продаж, динамика цен, структура доходов по направлениям.
F18: Себестоимость | I18: Прямые затраты: материалы, услуги, транспорт, логистика, и др.
F19: Операционные затраты | I19: Общие и административные расходы (аренда, маркетинг, связь, бухгалтерия, IT).
F20: Персонал | I20: Штат сотрудников и оплата труда
F21: Оборотный капитал | I21: Потребность в оборотном капитале
F22: Капитальные вложения | I22: Капитальные вложения и расчет амортизации
F23: Налоги | I23: Расчет налоговой нагрузки (Налог на прибыль, НДС)
F24: Финансирование | I24: Источнки финансирования и платежи (Долг, %, Собственный капитал)
D25: Отчетность | F25: P&L (Отчёт о прибылях и убытках) | I25: Отражает финансовый результат проекта по периодам.
F26: CF (Денежный поток) | I26: Отчёт о движении денежных средств (операционный, инвестиционный и финансовый потоки).
F27: Оценка эффективности | I27: Чистый дененжный поток, IRR, срока окупаемости.
D28: Результат | F28: - | I28: Сводка ключевых показателей по проекту, визуализация в виде графиков, анализ.
D31: Схема модели
D40: Условные обозначения
D42: 123 | E42: - ручной ввод данных
D43: =D42 -> 123 | E43: - ссылка на другой лист или блок
D44: =123*2/2 -> 123 | E44: - формула

Sheet Ввод
V3: 1 | W3: 1 | X3: 1 | Y3: 1 | Z3: 1 | AA3: 1 | AB3: 1 | AC3: 1 | AD3: 1 | AE3: 1 | AF3: 1 | AG3: 1 | AH3: =V3+1 -> 2 | AI3: =W3+1 -> 2 | AJ3: =X3+1 -> 2 | AK3: =Y3+1 -> 2 | AL3: =Z3+1 -> 2 | AM3: =AA3+1 -> 2 | AN3: =AB3+1 -> 2 | AO3: =AC3+1 -> 2 | ... CC3: =BQ3+1 -> 5
M4: FCFE | N4: =Отчетность!$L$83 -> 64235031 | P4: =YEAR(P8) -> 2021 | Q4: =YEAR(Q8) -> 2022 | R4: =YEAR(R8) -> 2023 | S4: =YEAR(S8) -> 2024 | T4: =YEAR(T8) -> 2025 | V4: =YEAR(V8) -> 2021 | W4: =YEAR(W8) -> 2021 | X4: =YEAR(X8) -> 2021 | Y4: =YEAR(Y8) -> 2021 | Z4: =YEAR(Z8) -> 2021 | AA4: =YEAR(AA8) -> 2021 | AB4: =YEAR(AB8) -> 2021 | AC4: =YEAR(AC8) -> 2021 | ... CC4: =YEAR(CC8) -> 2025
D5: Ввод | E5: Расчет | F5: Отчетность | G5: Результат | M5: IRR | N5: =Отчетность!$L$86 -> 0.89190128 | P5: 1 | Q5: =P5+1 -> 2 | R5: =Q5+1 -> 3 | S5: =R5+1 -> 4 | T5: =S5+1 -> 5 | V5: 1 | W5: =V5+1 -> 2 | X5: =W5+1 -> 3 | Y5: =X5+1 -> 4 | Z5: =Y5+1 -> 5 | AA5: =Z5+1 -> 6 | AB5: =AA5+1 -> 7 | AC5: =AB5+1 -> 8 | AD5: =AC5+1 -> 9 | ... CC5: =CB5+1 -> 60
V6: =MONTH(V8) -> 1 | W6: =MONTH(W8) -> 2 | X6: =MONTH(X8) -> 3 | Y6: =MONTH(Y8) -> 4 | Z6: =MONTH(Z8) -> 5 | AA6: =MONTH(AA8) -> 6 | AB6: =MONTH(AB8) -> 7 | AC6: =MONTH(AC8) -> 8 | ... CC6: =MONTH(CC8) -> 12
D8: Показатели | I8: Ед. изм | N8: Итого | P8: =M13 -> 44197 | Q8: =EOMONTH(P8,11)+1 -> 44562 | R8: =EOMONTH(Q8,11)+1 -> 44927 | S8: =EOMONTH(R8,11)+1 -> 45292 | T8: =EOMONTH(S8,11)+1 -> 45658 | V8: =M13 -> 44197 | W8: =EOMONTH(V8,0)+1 -> 44228 | X8: =EOMONTH(W8,0)+1 -> 44256 | Y8: =EOMONTH(X8,0)+1 -> 44287 | Z8: =EOMONTH(Y8,0)+1 -> 44317 | AA8: =EOMONTH(Z8,0)+1 -> 44348 | AB8: =EOMONTH(AA8,0)+1 -> 44378 | AC8: =EOMONTH(AB8,0)+1 -> 44409 | AD8: =EOMONTH(AC8,0)+1 -> 44440 | ... CC8: =EOMONTH(CB8,0)+1 -> 45992
D9: Общие настройки
D11: Название компании | I11: текст | M11: Строительства завода по производству винтовых свай
D12: Единицы измерения расчета модели | I12: текст | M12: руб
D13: Дата начала модели | I13: дата | M13: 44197
D15: Налоги
D17: НДС
D18: Ставка исходящего НДС (доходы) | I18: % | M18: 0.22
D19: Ставка входящего НДС (расходы) | I19: % | M19: 0.22
D20: Уменьшить НДС на входящий НДС? | I20: 1-да / 0-нет | M20: 1
D22: Налог на прибыль
D23: Выбор налогового режима | I23: выбор | J23: 1-УСН (Д), 2-УСН (Д-Р), 3-ОСН | M23: 3
D24: Ставка налога УСН (Доход) | I24: % | M24: 0.06
D25: Ставка налога УСН (Доход-Расход) | I25: % | M25: 0.15
D26: Ставка налога на прибыль ОСН | I26: % | M26: 0.25
D28: Выручка
D33: Себестоимость
D35: Коэффициент трубы в изделии | I35: % | M35: 0.25
D36: Коэффициент листа в изделии | I36: % | M36: 0.1
D37: Коэффициент расходных материалов в изделии | I37: % | M37: 0.05
D38: Коэффициент электроэнергии в изделии | I38: % | M38: 0.01
D39: Коэффициент коммунальных затрат в изделии | I39: % | M39: 0.01
D41: Операционные затраты
D43: Коммерческие затраты
D45: Коэффициент затрат на рекламу | I45: % | M45: 0.01
D46: Коэффициент затрат на упаковку | I46: % | M46: 0.01
D47: Коэффициент затрат на ГСМ | I47: % | M47: 0.01
D48: Коэффициент затрат на транспортировку | I48: % | M48: 0.003
D50: Общие и административные затраты
D55: Персонал
D61: Оборотный капитал
D63: Оборач. дебиторской задолженности | I63: дней | J63: Дней для расчета с клиентами | M63: 30
D64: Оборач. кредиторской задолженности | I64: дней | J64: Дней для расчета с подрядчиками | M64: 30
D65: Оборач. запасов | I65: дней | J65: Дней для производства товара | M65: 30
D67: Капитальные вложения
D73: Финансирование
...

Sheet Расчет
V3: =Ввод!V3 -> 1 | W3: =Ввод!W3 -> 1 | X3: =Ввод!X3 -> 1 | Y3: =Ввод!Y3 -> 1 | Z3: =Ввод!Z3 -> 1 | AA3: =Ввод!AA3 -> 1 | AB3: =Ввод!AB3 -> 1 | AC3: =Ввод!AC3 -> 1 | ... CC3: =Ввод!CC3 -> 5
M4: FCFE | N4: =Отчетность!$L$83 -> 64235031 | P4: =Ввод!P4 -> 2021 | Q4: =Ввод!Q4 -> 2022 | R4: =Ввод!R4 -> 2023 | S4: =Ввод!S4 -> 2024 | T4: =Ввод!T4 -> 2025 | V4: =Ввод!V4 -> 2021 | W4: =Ввод!W4 -> 2021 | X4: =Ввод!X4 -> 2021 | Y4: =Ввод!Y4 -> 2021 | Z4: =Ввод!Z4 -> 2021 | AA4: =Ввод!AA4 -> 2021 | AB4: =Ввод!AB4 -> 2021 | AC4: =Ввод!AC4 -> 2021 | ... CC4: =Ввод!CC4 -> 2025
D5: Ввод | E5: Расчет | F5: Отчетность | G5: Результат | M5: IRR | N5: =Отчетность!$L$86 -> 0.89190128 | P5: =Ввод!P5 -> 1 | Q5: =Ввод!Q5 -> 2 | R5: =Ввод!R5 -> 3 | S5: =Ввод!S5 -> 4 | T5: =Ввод!T5 -> 5 | V5: =Ввод!V5 -> 1 | W5: =Ввод!W5 -> 2 | X5: =Ввод!X5 -> 3 | Y5: =Ввод!Y5 -> 4 | Z5: =Ввод!Z5 -> 5 | AA5: =Ввод!AA5 -> 6 | AB5: =Ввод!AB5 -> 7 | AC5: =Ввод!AC5 -> 8 | ... CC5: =Ввод!CC5 -> 60
V6: =Ввод!V6 -> 1 | W6: =Ввод!W6 -> 2 | X6: =Ввод!X6 -> 3 | Y6: =Ввод!Y6 -> 4 | Z6: =Ввод!Z6 -> 5 | AA6: =Ввод!AA6 -> 6 | AB6: =Ввод!AB6 -> 7 | AC6: =Ввод!AC6 -> 8 | ... CC6: =Ввод!CC6 -> 12
D8: Показатели | I8: Ед. изм | N8: Итого | P8: =Ввод!P8 -> 44197 | Q8: =Ввод!Q8 -> 44562 | R8: =Ввод!R8 -> 44927 | S8: =Ввод!S8 -> 45292 | T8: =Ввод!T8 -> 45658 | V8: =Ввод!V8 -> 44197 | W8: =Ввод!W8 -> 44228 | X8: =Ввод!X8 -> 44256 | Y8: =Ввод!Y8 -> 44287 | Z8: =Ввод!Z8 -> 44317 | AA8: =Ввод!AA8 -> 44348 | AB8: =Ввод!AB8 -> 44378 | AC8: =Ввод!AC8 -> 44409 | ... CC8: =Ввод!CC8 -> 45992
D9: Выручка без НДС
D12: Предпосылки
D16: Расчет
D21: Итого | I21: =Ввод!$M$12 -> руб | N21: =SUM(P21:T21) -> 635000000 | P21: =SUMIF($V$4:$EK$4,P$4,$V21:$EK21) -> 44600000 | Q21: =SUMIF($V$4:$EK$4,Q$4,$V21:$EK21) -> 104400000 | R21: =SUMIF($V$4:$EK$4,R$4,$V21:$EK21) -> 133200000 | S21: =SUMIF($V$4:$EK$4,S$4,$V21:$EK21) -> 162000000 | T21: =SUMIF($V$4:$EK$4,T$4,$V21:$EK21) -> 190800000 | W21: 0 | X21: 0 | Y21: 0 | Z21: 0 | AA21: 5000000 | AB21: =AA21+500000 -> 5500000 | AC21: =AB21+500000 -> 6000000 | AD21: =AC21+500000 -> 6500000 | AE21: =AD21+500000 -> 7000000 | AF21: =AE21+200000 -> 7200000 | AG21: =AF21+200000 -> 7400000 | AH21: =AG21+200000 -> 7600000 | AI21: =AH21+200000 -> 7800000 | AJ21: =AI21+200000 -> 8000000 | AK21: =AJ21+200000 -> 8200000 | AL21: =AK21+200000 -> 8400000 | AM21: =AL21+200000 -> 8600000 | ... CC21: =CB21+200000 -> 17000000
D22: Рост | I22: % | P22: =IFERROR((P21-O21)/O21,0) -> 0 | Q22: =IFERROR((Q21-P21)/P21,0) -> 1.3408072 | R22: =IFERROR((R21-Q21)/Q21,0) -> 0.27586207 | S22: =IFERROR((S21-R21)/R21,0) -> 0.21621622 | T22: =IFERROR((T21-S21)/S21,0) -> 0.17777778 | V22: =IFERROR((V21-U21)/U21,0) -> 0 | W22: =IFERROR((W21-V21)/V21,0) -> 0 | X22: =IFERROR((X21-W21)/W21,0) -> 0 | Y22: =IFERROR((Y21-X21)/X21,0) -> 0 | Z22: =IFERROR((Z21-Y21)/Y21,0) -> 0 | AA22: =IFERROR((AA21-Z21)/Z21,0) -> 0 | AB22: =IFERROR((AB21-AA21)/AA21,0) -> 0.1 | AC22: =IFERROR((AC21-AB21)/AB21,0) -> 0.090909091 | ... CC22: =IFERROR((CC21-CB21)/CB21,0) -> 0.011904762
D24: Итого выручка | I24: =Ввод!$M$12 -> руб | N24: =SUM(P24:T24) -> 635000000 | P24: =SUMIF($V$4:$EK$4,P$4,$V24:$EK24) -> 44600000 | Q24: =SUMIF($V$4:$EK$4,Q$4,$V24:$EK24) -> 104400000 | R24: =SUMIF($V$4:$EK$4,R$4,$V24:$EK24) -> 133200000 | S24: =SUMIF($V$4:$EK$4,S$4,$V24:$EK24) -> 162000000 | T24: =SUMIF($V$4:$EK$4,T$4,$V24:$EK24) -> 190800000 | V24: =V21 -> 0 | W24: =W21 -> 0 | X24: =X21 -> 0 | Y24: =Y21 -> 0 | Z24: =Z21 -> 0 | AA24: =AA21 -> 5000000 | AB24: =AB21 -> 5500000 | AC24: =AC21 -> 6000000 | ... CC24: =CC21 -> 17000000
D25: Рост | I25: % | P25: =IFERROR((P24-O24)/O24,0) -> 0 | Q25: =IFERROR((Q24-P24)/P24,0) -> 1.3408072 | R25: =IFERROR((R24-Q24)/Q24,0) -> 0.27586207 | S25: =IFERROR((S24-R24)/R24,0) -> 0.21621622 | T25: =IFERROR((T24-S24)/S24,0) -> 0.17777778 | V25: =IFERROR((V24-U24)/U24,0) -> 0 | W25: =IFERROR((W24-V24)/V24,0) -> 0 | X25: =IFERROR((X24-W24)/W24,0) -> 0 | Y25: =IFERROR((Y24-X24)/X24,0) -> 0 | Z25: =IFERROR((Z24-Y24)/Y24,0) -> 0 | AA25: =IFERROR((AA24-Z24)/Z24,0) -> 0 | AB25: =IFERROR((AB24-AA24)/AA24,0) -> 0.1 | AC25: =IFERROR((AC24-AB24)/AB24,0) -> 0.090909091 | ... CC25: =IFERROR((CC24-CB24)/CB24,0) -> 0.011904762
D27: Себестоимость без НДС
D29: Предпосылки
D33: Расчет
D34: Труба г/к | I34: =Ввод!$M$12 -> руб | N34: =SUM(P34:T34) -> -158750000 | P34: =SUMIF($V$4:$EK$4,P$4,$V34:$EK34) -> -11150000 | Q34: =SUMIF($V$4:$EK$4,Q$4,$V34:$EK34) -> -26100000 | R34: =SUMIF($V$4:$EK$4,R$4,$V34:$EK34) -> -33300000 | S34: =SUMIF($V$4:$EK$4,S$4,$V34:$EK34) -> -40500000 | T34: =SUMIF($V$4:$EK$4,T$4,$V34:$EK34) -> -47700000 | W34: 0 | X34: 0 | Y34: 0 | Z34: 0 | AA34: =(AA21*Ввод!$M$35)*-1 -> -1250000 | AB34: =(AB21*Ввод!$M$35)*-1 -> -1375000 | AC34: =(AC21*Ввод!$M$35)*-1 -> -1500000 | AD34: =(AD21*Ввод!$M$35)*-1 -> -1625000 | AE34: =(AE21*Ввод!$M$35)*-1 -> -1750000 | AF34: =(AF21*Ввод!$M$35)*-1 -> -1800000 | AG34: =(AG21*Ввод!$M$35)*-1 -> -1850000 | AH34: =(AH21*Ввод!$M$35)*-1 -> -1900000 | ... CC34: =(CC21*Ввод!$M$35)*-1 -> -4250000
D35: Лист г/к | I35: =Ввод!$M$12 -> руб | N35: =SUM(P35:T35) -> -63500000 | P35: =SUMIF($V$4:$EK$4,P$4,$V35:$EK35) -> -4460000 | Q35: =SUMIF($V$4:$EK$4,Q$4,$V35:$EK35) -> -10440000 | R35: =SUMIF($V$4:$EK$4,R$4,$V35:$EK35) -> -13320000 | S35: =SUMIF($V$4:$EK$4,S$4,$V35:$EK35) -> -16200000 | T35: =SUMIF($V$4:$EK$4,T$4,$V35:$EK35) -> -19080000 | W35: 0 | X35: 0 | Y35: 0 | Z35: 0 | AA35: =(AA21*Ввод!$M$36)*-1 -> -500000 | AB35: =(AB21*Ввод!$M$36)*-1 -> -550000 | AC35: =(AC21*Ввод!$M$36)*-1 -> -600000 | AD35: =(AD21*Ввод!$M$36)*-1 -> -650000 | AE35: =(AE21*Ввод!$M$36)*-1 -> -700000 | AF35: =(AF21*Ввод!$M$36)*-1 -> -720000 | AG35: =(AG21*Ввод!$M$36)*-1 -> -740000 | AH35: =(AH21*Ввод!$M$36)*-1 -> -760000 | ... CC35: =(CC21*Ввод!$M$36)*-1 -> -1700000
D36: Расходные материалы | I36: =Ввод!$M$12 -> руб | N36: =SUM(P36:T36) -> -31750000 | P36: =SUMIF($V$4:$EK$4,P$4,$V36:$EK36) -> -2230000 | Q36: =SUMIF($V$4:$EK$4,Q$4,$V36:$EK36) -> -5220000 | R36: =SUMIF($V$4:$EK$4,R$4,$V36:$EK36) -> -6660000 | S36: =SUMIF($V$4:$EK$4,S$4,$V36:$EK36) -> -8100000 | T36: =SUMIF($V$4:$EK$4,T$4,$V36:$EK36) -> -9540000 | W36: 0 | X36: 0 | Y36: 0 | Z36: 0 | AA36: =(AA21*Ввод!$M$37)*-1 -> -250000 | AB36: =(AB21*Ввод!$M$37)*-1 -> -275000 | AC36: =(AC21*Ввод!$M$37)*-1 -> -300000 | AD36: =(AD21*Ввод!$M$37)*-1 -> -325000 | AE36: =(AE21*Ввод!$M$37)*-1 -> -350000 | AF36: =(AF21*Ввод!$M$37)*-1 -> -360000 | AG36: =(AG21*Ввод!$M$37)*-1 -> -370000 | AH36: =(AH21*Ввод!$M$37)*-1 -> -380000 | ... CC36: =(CC21*Ввод!$M$37)*-1 -> -850000
D37: Электроэнергия | I37: =Ввод!$M$12 -> руб | N37: =SUM(P37:T37) -> -6350000 | P37: =SUMIF($V$4:$EK$4,P$4,$V37:$EK37) -> -446000 | Q37: =SUMIF($V$4:$EK$4,Q$4,$V37:$EK37) -> -1044000 | R37: =SUMIF($V$4:$EK$4,R$4,$V37:$EK37) -> -1332000 | S37: =SUMIF($V$4:$EK$4,S$4,$V37:$EK37) -> -1620000 | T37: =SUMIF($V$4:$EK$4,T$4,$V37:$EK37) -> -1908000 | W37: 0 | X37: 0 | Y37: 0 | Z37: 0 | AA37: =(AA21*Ввод!$M$38)*-1 -> -50000 | AB37: =(AB21*Ввод!$M$38)*-1 -> -55000 | AC37: =(AC21*Ввод!$M$38)*-1 -> -60000 | AD37: =(AD21*Ввод!$M$38)*-1 -> -65000 | AE37: =(AE21*Ввод!$M$38)*-1 -> -70000 | AF37: =(AF21*Ввод!$M$38)*-1 -> -72000 | AG37: =(AG21*Ввод!$M$38)*-1 -> -74000 | AH37: =(AH21*Ввод!$M$38)*-1 -> -76000 | ... CC37: =(CC21*Ввод!$M$38)*-1 -> -170000
D38: Коммунальные расходы | I38: =Ввод!$M$12 -> руб | N38: =SUM(P38:T38) -> -6350000 | P38: =SUMIF($V$4:$EK$4,P$4,$V38:$EK38) -> -446000 | Q38: =SUMIF($V$4:$EK$4,Q$4,$V38:$EK38) -> -1044000 | R38: =SUMIF($V$4:$EK$4,R$4,$V38:$EK38) -> -1332000 | S38: =SUMIF($V$4:$EK$4,S$4,$V38:$EK38) -> -1620000 | T38: =SUMIF($V$4:$EK$4,T$4,$V38:$EK38) -> -1908000 | W38: 0 | X38: 0 | Y38: 0 | Z38: 0 | AA38: =(AA21*Ввод!$M$39)*-1 -> -50000 | AB38: =(AB21*Ввод!$M$39)*-1 -> -55000 | AC38: =(AC21*Ввод!$M$39)*-1 -> -60000 | AD38: =(AD21*Ввод!$M$39)*-1 -> -65000 | AE38: =(AE21*Ввод!$M$39)*-1 -> -70000 | AF38: =(AF21*Ввод!$M$39)*-1 -> -72000 | AG38: =(AG21*Ввод!$M$39)*-1 -> -74000 | AH38: =(AH21*Ввод!$M$39)*-1 -> -76000 | ... CC38: =(CC21*Ввод!$M$39)*-1 -> -170000
D40: Итого себестоимость | I40: =Ввод!$M$12 -> руб | N40: =SUM(P40:T40) -> -266700000 | P40: =SUMIF($V$4:$CC$4,P$4,$V40:$CC40) -> -18732000 | Q40: =SUMIF($V$4:$CC$4,Q$4,$V40:$CC40) -> -43848000 | R40: =SUMIF($V$4:$CC$4,R$4,$V40:$CC40) -> -55944000 | S40: =SUMIF($V$4:$CC$4,S$4,$V40:$CC40) -> -68040000 | T40: =SUMIF($V$4:$CC$4,T$4,$V40:$CC40) -> -80136000 | V40: =SUM(V34:V38) -> 0 | W40: =SUM(W34:W38) -> 0 | X40: =SUM(X34:X38) -> 0 | Y40: =SUM(Y34:Y38) -> 0 | Z40: =SUM(Z34:Z38) -> 0 | AA40: =SUM(AA34:AA38) -> -2100000 | AB40: =SUM(AB34:AB38) -> -2310000 | AC40: =SUM(AC34:AC38) -> -2520000 | ... CC40: =SUM(CC34:CC38) -> -7140000
D42: Операционные затраты без НДС
D44: Коммерческие затраты
D46: Предпосылки
D50: Расчет
D51: Реклама | I51: =Ввод!$M$12 -> руб | N51: =SUM(P51:T51) -> -6350000 | P51: =SUMIF($V$4:$EK$4,P$4,$V51:$EK51) -> -446000 | Q51: =SUMIF($V$4:$EK$4,Q$4,$V51:$EK51) -> -1044000 | R51: =SUMIF($V$4:$EK$4,R$4,$V51:$EK51) -> -1332000 | S51: =SUMIF($V$4:$EK$4,S$4,$V51:$EK51) -> -1620000 | T51: =SUMIF($V$4:$EK$4,T$4,$V51:$EK51) -> -1908000 | V51: 0 | W51: 0 | X51: 0 | Y51: 0 | Z51: 0 | AA51: =(AA21*Ввод!$M$45)*-1 -> -50000 | AB51: =(AB21*Ввод!$M$45)*-1 -> -55000 | AC51: =(AC21*Ввод!$M$45)*-1 -> -60000 | AD51: =(AD21*Ввод!$M$45)*-1 -> -65000 | AE51: =(AE21*Ввод!$M$45)*-1 -> -70000 | AF51: =(AF21*Ввод!$M$45)*-1 -> -72000 | AG51: =(AG21*Ввод!$M$45)*-1 -> -74000 | AH51: =(AH21*Ввод!$M$45)*-1 -> -76000 | ... CC51: =(CC21*Ввод!$M$45)*-1 -> -170000
D52: Упаковка и маркировка | I52: =Ввод!$M$12 -> руб | N52: =SUM(P52:T52) -> -6350000 | P52: =SUMIF($V$4:$EK$4,P$4,$V52:$EK52) -> -446000 | Q52: =SUMIF($V$4:$EK$4,Q$4,$V52:$EK52) -> -1044000 | R52: =SUMIF($V$4:$EK$4,R$4,$V52:$EK52) -> -1332000 | S52: =SUMIF($V$4:$EK$4,S$4,$V52:$EK52) -> -1620000 | T52: =SUMIF($V$4:$EK$4,T$4,$V52:$EK52) -> -1908000 | V52: 0 | W52: 0 | X52: 0 | Y52: 0 | Z52: 0 | AA52: =(AA21*Ввод!$M$46)*-1 -> -50000 | AB52: =(AB21*Ввод!$M$46)*-1 -> -55000 | AC52: =(AC21*Ввод!$M$46)*-1 -> -60000 | AD52: =(AD21*Ввод!$M$46)*-1 -> -65000 | AE52: =(AE21*Ввод!$M$46)*-1 -> -70000 | AF52: =(AF21*Ввод!$M$46)*-1 -> -72000 | AG52: =(AG21*Ввод!$M$46)*-1 -> -74000 | AH52: =(AH21*Ввод!$M$46)*-1 -> -76000 | ... CC52: =(CC21*Ввод!$M$46)*-1 -> -170000
D53: ГСМ | I53: =Ввод!$M$12 -> руб | N53: =SUM(P53:T53) -> -6350000 | P53: =SUMIF($V$4:$EK$4,P$4,$V53:$EK53) -> -446000 | Q53: =SUMIF($V$4:$EK$4,Q$4,$V53:$EK53) -> -1044000 | R53: =SUMIF($V$4:$EK$4,R$4,$V53:$EK53) -> -1332000 | S53: =SUMIF($V$4:$EK$4,S$4,$V53:$EK53) -> -1620000 | T53: =SUMIF($V$4:$EK$4,T$4,$V53:$EK53) -> -1908000 | V53: 0 | W53: 0 | X53: 0 | Y53: 0 | Z53: 0 | AA53: =(AA21*Ввод!$M$47)*-1 -> -50000 | AB53: =(AB21*Ввод!$M$47)*-1 -> -55000 | AC53: =(AC21*Ввод!$M$47)*-1 -> -60000 | AD53: =(AD21*Ввод!$M$47)*-1 -> -65000 | AE53: =(AE21*Ввод!$M$47)*-1 -> -70000 | AF53: =(AF21*Ввод!$M$47)*-1 -> -72000 | AG53: =(AG21*Ввод!$M$47)*-1 -> -74000 | AH53: =(AH21*Ввод!$M$47)*-1 -> -76000 | ... CC53: =(CC21*Ввод!$M$47)*-1 -> -170000
D54: Расходы на транспортировку | I54: =Ввод!$M$12 -> руб | N54: =SUM(P54:T54) -> -1905000 | P54: =SUMIF($V$4:$EK$4,P$4,$V54:$EK54) -> -133800 | Q54: =SUMIF($V$4:$EK$4,Q$4,$V54:$EK54) -> -313200 | R54: =SUMIF($V$4:$EK$4,R$4,$V54:$EK54) -> -399600 | S54: =SUMIF($V$4:$EK$4,S$4,$V54:$EK54) -> -486000 | T54: =SUMIF($V$4:$EK$4,T$4,$V54:$EK54) -> -572400 | V54: 0 | W54: 0 | X54: 0 | Y54: 0 | Z54: 0 | AA54: =(AA21*Ввод!$M$48)*-1 -> -15000 | AB54: =(AB21*Ввод!$M$48)*-1 -> -16500 | AC54: =(AC21*Ввод!$M$48)*-1 -> -18000 | AD54: =(AD21*Ввод!$M$48)*-1 -> -19500 | AE54: =(AE21*Ввод!$M$48)*-1 -> -21000 | AF54: =(AF21*Ввод!$M$48)*-1 -> -21600 | AG54: =(AG21*Ввод!$M$48)*-1 -> -22200 | AH54: =(AH21*Ввод!$M$48)*-1 -> -22800 | ... CC54: =(CC21*Ввод!$M$48)*-1 -> -51000
D55: Коммерческие затраты | I55: =Ввод!$M$12 -> руб | N55: =SUM(P55:T55) -> -20955000 | P55: =SUMIF($V$4:$CC$4,P$4,$V55:$CC55) -> -1471800 | Q55: =SUMIF($V$4:$CC$4,Q$4,$V55:$CC55) -> -3445200 | R55: =SUMIF($V$4:$CC$4,R$4,$V55:$CC55) -> -4395600 | S55: =SUMIF($V$4:$CC$4,S$4,$V55:$CC55) -> -5346000 | T55: =SUMIF($V$4:$CC$4,T$4,$V55:$CC55) -> -6296400 | V55: =SUM(V51:V54) -> 0 | W55: =SUM(W51:W54) -> 0 | X55: =SUM(X51:X54) -> 0 | Y55: =SUM(Y51:Y54) -> 0 | Z55: =SUM(Z51:Z54) -> 0 | AA55: =SUM(AA51:AA54) -> -165000 | AB55: =SUM(AB51:AB54) -> -181500 | AC55: =SUM(AC51:AC54) -> -198000 | ... CC55: =SUM(CC51:CC54) -> -561000
D57: Общие и административные затраты
D59: Предпосылки
D64: Расчет
D65: Расходы на управление | I65: =Ввод!$M$12 -> руб | N65: =SUM(P65:T65) -> -6000000 | P65: =SUMIF($V$4:$EK$4,P$4,$V65:$EK65) -> -1200000 | Q65: =SUMIF($V$4:$EK$4,Q$4,$V65:$EK65) -> -1200000 | R65: =SUMIF($V$4:$EK$4,R$4,$V65:$EK65) -> -1200000 | S65: =SUMIF($V$4:$EK$4,S$4,$V65:$EK65) -> -1200000 | T65: =SUMIF($V$4:$EK$4,T$4,$V65:$EK65) -> -1200000 | V65: -100000 | W65: -100000 | X65: -100000 | Y65: -100000 | Z65: -100000 | AA65: -100000 | AB65: -100000 | AC65: -100000 | AD65: -100000 | AE65: -100000 | AF65: -100000 | AG65: -100000 | AH65: -100000 | AI65: -100000 | AJ65: -100000 | AK65: -100000 | AL65: -100000 | AM65: -100000 | AN65: -100000 | AO65: -100000 | AP65: -100000 | AQ65: -100000 | AR65: -100000 | AS65: -100000 | AT65: -100000 | AU65: -100000 | AV65: -100000 | AW65: -100000 | AX65: -100000 | AY65: -100000 | AZ65: -100000 | BA65: -100000 | BB65: -100000 | BC65: -100000 | BD65: -100000 | BE65: -100000 | BF65: -100000 | BG65: -100000 | BH65: -100000 | BI65: -100000 | BJ65: -100000 | BK65: -100000 | BL65: -100000 | BM65: -100000 | BN65: -100000 | BO65: -100000 | BP65: -100000 | BQ65: -100000 | BR65: -100000 | BS65: -100000 | BT65: -100000 | BU65: -100000 | BV65: -100000 | BW65: -100000 | BX65: -100000 | BY65: -100000 | BZ65: -100000 | CA65: -100000 | CB65: -100000 | CC65: -100000
D66: Содержание имущества | I66: =Ввод!$M$12 -> руб | N66: =SUM(P66:T66) -> -5550000 | P66: =SUMIF($V$4:$EK$4,P$4,$V66:$EK66) -> -750000 | Q66: =SUMIF($V$4:$EK$4,Q$4,$V66:$EK66) -> -1200000 | R66: =SUMIF($V$4:$EK$4,R$4,$V66:$EK66) -> -1200000 | S66: =SUMIF($V$4:$EK$4,S$4,$V66:$EK66) -> -1200000 | T66: =SUMIF($V$4:$EK$4,T$4,$V66:$EK66) -> -1200000 | V66: -10000 | W66: -10000 | X66: -10000 | Y66: -10000 | Z66: -10000 | AA66: -100000 | AB66: -100000 | AC66: -100000 | AD66: -100000 | AE66: -100000 | AF66: -100000 | AG66: -100000 | AH66: -100000 | AI66: -100000 | AJ66: -100000 | AK66: -100000 | AL66: -100000 | AM66: -100000 | AN66: -100000 | AO66: -100000 | AP66: -100000 | AQ66: -100000 | AR66: -100000 | AS66: -100000 | AT66: -100000 | AU66: -100000 | AV66: -100000 | AW66: -100000 | AX66: -100000 | AY66: -100000 | AZ66: -100000 | BA66: -100000 | BB66: -100000 | BC66: -100000 | BD66: -100000 | BE66: -100000 | BF66: -100000 | BG66: -100000 | BH66: -100000 | BI66: -100000 | BJ66: -100000 | BK66: -100000 | BL66: -100000 | BM66: -100000 | BN66: -100000 | BO66: -100000 | BP66: -100000 | BQ66: -100000 | BR66: -100000 | BS66: -100000 | BT66: -100000 | BU66: -100000 | BV66: -100000 | BW66: -100000 | BX66: -100000 | BY66: -100000 | BZ66: -100000 | CA66: -100000 | CB66: -100000 | CC66: -100000
D67: Связь, IT и офисные расходы | I67: =Ввод!$M$12 -> руб | N67: =SUM(P67:T67) -> -5750000 | P67: =SUMIF($V$4:$EK$4,P$4,$V67:$EK67) -> -950000 | Q67: =SUMIF($V$4:$EK$4,Q$4,$V67:$EK67) -> -1200000 | R67: =SUMIF($V$4:$EK$4,R$4,$V67:$EK67) -> -1200000 | S67: =SUMIF($V$4:$EK$4,S$4,$V67:$EK67) -> -1200000 | T67: =SUMIF($V$4:$EK$4,T$4,$V67:$EK67) -> -1200000 | V67: -50000 | W67: -50000 | X67: -50000 | Y67: -50000 | Z67: -50000 | AA67: -100000 | AB67: -100000 | AC67: -100000 | AD67: -100000 | AE67: -100000 | AF67: -100000 | AG67: -100000 | AH67: -100000 | AI67: -100000 | AJ67: -100000 | AK67: -100000 | AL67: -100000 | AM67: -100000 | AN67: -100000 | AO67: -100000 | AP67: -100000 | AQ67: -100000 | AR67: -100000 | AS67: -100000 | AT67: -100000 | AU67: -100000 | AV67: -100000 | AW67: -100000 | AX67: -100000 | AY67: -100000 | AZ67: -100000 | BA67: -100000 | BB67: -100000 | BC67: -100000 | BD67: -100000 | BE67: -100000 | BF67: -100000 | BG67: -100000 | BH67: -100000 | BI67: -100000 | BJ67: -100000 | BK67: -100000 | BL67: -100000 | BM67: -100000 | BN67: -100000 | BO67: -100000 | BP67: -100000 | BQ67: -100000 | BR67: -100000 | BS67: -100000 | BT67: -100000 | BU67: -100000 | BV67: -100000 | BW67: -100000 | BX67: -100000 | BY67: -100000 | BZ67: -100000 | CA67: -100000 | CB67: -100000 | CC67: -100000
D68: Налоги, сборы, прочие расходы | I68: =Ввод!$M$12 -> руб | N68: =SUM(P68:T68) -> -11500000 | P68: =SUMIF($V$4:$EK$4,P$4,$V68:$EK68) -> -1900000 | Q68: =SUMIF($V$4:$EK$4,Q$4,$V68:$EK68) -> -2400000 | R68: =SUMIF($V$4:$EK$4,R$4,$V68:$EK68) -> -2400000 | S68: =SUMIF($V$4:$EK$4,S$4,$V68:$EK68) -> -2400000 | T68: =SUMIF($V$4:$EK$4,T$4,$V68:$EK68) -> -2400000 | V68: -100000 | W68: -100000 | X68: -100000 | Y68: -100000 | Z68: -100000 | AA68: -200000 | AB68: -200000 | AC68: -200000 | AD68: -200000 | AE68: -200000 | AF68: -200000 | AG68: -200000 | AH68: -200000 | AI68: -200000 | AJ68: -200000 | AK68: -200000 | AL68: -200000 | AM68: -200000 | AN68: -200000 | AO68: -200000 | AP68: -200000 | AQ68: -200000 | AR68: -200000 | AS68: -200000 | AT68: -200000 | AU68: -200000 | AV68: -200000 | AW68: -200000 | AX68: -200000 | AY68: -200000 | AZ68: -200000 | BA68: -200000 | BB68: -200000 | BC68: -200000 | BD68: -200000 | BE68: -200000 | BF68: -200000 | BG68: -200000 | BH68: -200000 | BI68: -200000 | BJ68: -200000 | BK68: -200000 | BL68: -200000 | BM68: -200000 | BN68: -200000 | BO68: -200000 | BP68: -200000 | BQ68: -200000 | BR68: -200000 | BS68: -200000 | BT68: -200000 | BU68: -200000 | BV68: -200000 | BW68: -200000 | BX68: -200000 | BY68: -200000 | BZ68: -200000 | CA68: -200000 | CB68: -200000 | CC68: -200000
D69: Общие и административные затраты | I69: =Ввод!$M$12 -> руб | N69: =SUM(P69:T69) -> -28800000 | P69: =SUMIF($V$4:$CC$4,P$4,$V69:$CC69) -> -4800000 | Q69: =SUMIF($V$4:$CC$4,Q$4,$V69:$CC69) -> -6000000 | R69: =SUMIF($V$4:$CC$4,R$4,$V69:$CC69) -> -6000000 | S69: =SUMIF($V$4:$CC$4,S$4,$V69:$CC69) -> -6000000 | T69: =SUMIF($V$4:$CC$4,T$4,$V69:$CC69) -> -6000000 | V69: =SUM(V65:V68) -> -260000 | W69: =SUM(W65:W68) -> -260000 | X69: =SUM(X65:X68) -> -260000 | Y69: =SUM(Y65:Y68) -> -260000 | Z69: =SUM(Z65:Z68) -> -260000 | AA69: =SUM(AA65:AA68) -> -500000 | AB69: =SUM(AB65:AB68) -> -500000 | AC69: =SUM(AC65:AC68) -> -500000 | ... CC69: =SUM(CC65:CC68) -> -500000
D71: Операционные затраты | I71: =Ввод!$M$12 -> руб | N71: =SUM(P71:T71) -> -49755000 | P71: =SUMIF($V$4:$CC$4,P$4,$V71:$CC71) -> -6271800 | Q71: =SUMIF($V$4:$CC$4,Q$4,$V71:$CC71) -> -9445200 | R71: =SUMIF($V$4:$CC$4,R$4,$V71:$CC71) -> -10395600 | S71: =SUMIF($V$4:$CC$4,S$4,$V71:$CC71) -> -11346000 | T71: =SUMIF($V$4:$CC$4,T$4,$V71:$CC71) -> -12296400 | V71: =V55+V69 -> -260000 | W71: =W55+W69 -> -260000 | X71: =X55+X69 -> -260000 | Y71: =Y55+Y69 -> -260000 | Z71: =Z55+Z69 -> -260000 | AA71: =AA55+AA69 -> -665000 | AB71: =AB55+AB69 -> -681500 | AC71: =AC55+AC69 -> -698000 | ... CC71: =CC55+CC69 -> -1061000
D73: Персонал
...

Sheet Отчетность
T3: =Ввод!V3 -> 1 | U3: =Ввод!W3 -> 1 | V3: =Ввод!X3 -> 1 | W3: =Ввод!Y3 -> 1 | X3: =Ввод!Z3 -> 1 | Y3: =Ввод!AA3 -> 1 | Z3: =Ввод!AB3 -> 1 | AA3: =Ввод!AC3 -> 1 | ... CA3: =Ввод!CC3 -> 5
K4: FCFE | L4: =Отчетность!$L$83 -> 64235031 | N4: =Ввод!P4 -> 2021 | O4: =Ввод!Q4 -> 2022 | P4: =Ввод!R4 -> 2023 | Q4: =Ввод!S4 -> 2024 | R4: =Ввод!T4 -> 2025 | T4: =Ввод!V4 -> 2021 | U4: =Ввод!W4 -> 2021 | V4: =Ввод!X4 -> 2021 | W4: =Ввод!Y4 -> 2021 | X4: =Ввод!Z4 -> 2021 | Y4: =Ввод!AA4 -> 2021 | Z4: =Ввод!AB4 -> 2021 | AA4: =Ввод!AC4 -> 2021 | ... CA4: =Ввод!CC4 -> 2025
D5: Ввод | E5: Расчет | F5: Отчетность | G5: Результат | K5: IRR | L5: =Отчетность!$L$86 -> 0.89190128 | N5: =Ввод!P5 -> 1 | O5: =Ввод!Q5 -> 2 | P5: =Ввод!R5 -> 3 | Q5: =Ввод!S5 -> 4 | R5: =Ввод!T5 -> 5 | T5: =Ввод!V5 -> 1 | U5: =Ввод!W5 -> 2 | V5: =Ввод!X5 -> 3 | W5: =Ввод!Y5 -> 4 | X5: =Ввод!Z5 -> 5 | Y5: =Ввод!AA5 -> 6 | Z5: =Ввод!AB5 -> 7 | AA5: =Ввод!AC5 -> 8 | ... CA5: =Ввод!CC5 -> 60
T6: =Ввод!V6 -> 1 | U6: =Ввод!W6 -> 2 | V6: =Ввод!X6 -> 3 | W6: =Ввод!Y6 -> 4 | X6: =Ввод!Z6 -> 5 | Y6: =Ввод!AA6 -> 6 | Z6: =Ввод!AB6 -> 7 | AA6: =Ввод!AC6 -> 8 | ... CA6: =Ввод!CC6 -> 12
D8: Показатели | I8: Ед. изм | L8: Итого | N8: =Ввод!P8 -> 44197 | O8: =Ввод!Q8 -> 44562 | P8: =Ввод!R8 -> 44927 | Q8: =Ввод!S8 -> 45292 | R8: =Ввод!T8 -> 45658 | T8: =Ввод!V8 -> 44197 | U8: =Ввод!W8 -> 44228 | V8: =Ввод!X8 -> 44256 | W8: =Ввод!Y8 -> 44287 | X8: =Ввод!Z8 -> 44317 | Y8: =Ввод!AA8 -> 44348 | Z8: =Ввод!AB8 -> 44378 | AA8: =Ввод!AC8 -> 44409 | ... CA8: =Ввод!CC8 -> 45992
D9: Отчет о прибылях и убытках - P&L
D11: Выручка | I11: =Ввод!$M$12 -> руб | L11: =SUM(N11:R11) -> 635000000 | N11: =SUMIF($T$4:$EI$4,N$4,$T11:$EI11) -> 44600000 | O11: =SUMIF($T$4:$EI$4,O$4,$T11:$EI11) -> 104400000 | P11: =SUMIF($T$4:$EI$4,P$4,$T11:$EI11) -> 133200000 | Q11: =SUMIF($T$4:$EI$4,Q$4,$T11:$EI11) -> 162000000 | R11: =SUMIF($T$4:$EI$4,R$4,$T11:$EI11) -> 190800000 | T11: =Расчет!V24 -> 0 | U11: =Расчет!W24 -> 0 | V11: =Расчет!X24 -> 0 | W11: =Расчет!Y24 -> 0 | X11: =Расчет!Z24 -> 0 | Y11: =Расчет!AA24 -> 5000000 | Z11: =Расчет!AB24 -> 5500000 | AA11: =Расчет!AC24 -> 6000000 | ... CA11: =Расчет!CC24 -> 17000000
D13: Себестоимость | I13: =Ввод!$M$12 -> руб | L13: =SUM(N13:R13) -> -266700000 | N13: =SUMIF($T$4:$EI$4,N$4,$T13:$EI13) -> -18732000 | O13: =SUMIF($T$4:$EI$4,O$4,$T13:$EI13) -> -43848000 | P13: =SUMIF($T$4:$EI$4,P$4,$T13:$EI13) -> -55944000 | Q13: =SUMIF($T$4:$EI$4,Q$4,$T13:$EI13) -> -68040000 | R13: =SUMIF($T$4:$EI$4,R$4,$T13:$EI13) -> -80136000 | T13: =Расчет!V40 -> 0 | U13: =Расчет!W40 -> 0 | V13: =Расчет!X40 -> 0 | W13: =Расчет!Y40 -> 0 | X13: =Расчет!Z40 -> 0 | Y13: =Расчет!AA40 -> -2100000 | Z13: =Расчет!AB40 -> -2310000 | AA13: =Расчет!AC40 -> -2520000 | ... CA13: =Расчет!CC40 -> -7140000
D14: =Расчет!D34 -> Труба г/к | I14: =Ввод!$M$12 -> руб | L14: =SUM(N14:R14) -> -158750000 | N14: =SUMIF($T$4:$EI$4,N$4,$T14:$EI14) -> -11150000 | O14: =SUMIF($T$4:$EI$4,O$4,$T14:$EI14) -> -26100000 | P14: =SUMIF($T$4:$EI$4,P$4,$T14:$EI14) -> -33300000 | Q14: =SUMIF($T$4:$EI$4,Q$4,$T14:$EI14) -> -40500000 | R14: =SUMIF($T$4:$EI$4,R$4,$T14:$EI14) -> -47700000 | T14: =Расчет!V34 -> 0 | U14: =Расчет!W34 -> 0 | V14: =Расчет!X34 -> 0 | W14: =Расчет!Y34 -> 0 | X14: =Расчет!Z34 -> 0 | Y14: =Расчет!AA34 -> -1250000 | Z14: =Расчет!AB34 -> -1375000 | AA14: =Расчет!AC34 -> -1500000 | ... CA14: =Расчет!CC34 -> -4250000
D15: =Расчет!D35 -> Лист г/к | I15: =Ввод!$M$12 -> руб | L15: =SUM(N15:R15) -> -63500000 | N15: =SUMIF($T$4:$EI$4,N$4,$T15:$EI15) -> -4460000 | O15: =SUMIF($T$4:$EI$4,O$4,$T15:$EI15) -> -10440000 | P15: =SUMIF($T$4:$EI$4,P$4,$T15:$EI15) -> -13320000 | Q15: =SUMIF($T$4:$EI$4,Q$4,$T15:$EI15) -> -16200000 | R15: =SUMIF($T$4:$EI$4,R$4,$T15:$EI15) -> -19080000 | T15: =Расчет!V35 -> 0 | U15: =Расчет!W35 -> 0 | V15: =Расчет!X35 -> 0 | W15: =Расчет!Y35 -> 0 | X15: =Расчет!Z35 -> 0 | Y15: =Расчет!AA35 -> -500000 | Z15: =Расчет!AB35 -> -550000 | AA15: =Расчет!AC35 -> -600000 | ... CA15: =Расчет!CC35 -> -1700000
D16: =Расчет!D36 -> Расходные материалы | I16: =Ввод!$M$12 -> руб | L16: =SUM(N16:R16) -> -31750000 | N16: =SUMIF($T$4:$EI$4,N$4,$T16:$EI16) -> -2230000 | O16: =SUMIF($T$4:$EI$4,O$4,$T16:$EI16) -> -5220000 | P16: =SUMIF($T$4:$EI$4,P$4,$T16:$EI16) -> -6660000 | Q16: =SUMIF($T$4:$EI$4,Q$4,$T16:$EI16) -> -8100000 | R16: =SUMIF($T$4:$EI$4,R$4,$T16:$EI16) -> -9540000 | T16: =Расчет!V36 -> 0 | U16: =Расчет!W36 -> 0 | V16: =Расчет!X36 -> 0 | W16: =Расчет!Y36 -> 0 | X16: =Расчет!Z36 -> 0 | Y16: =Расчет!AA36 -> -250000 | Z16: =Расчет!AB36 -> -275000 | AA16: =Расчет!AC36 -> -300000 | ... CA16: =Расчет!CC36 -> -850000
D17: =Расчет!D38 -> Коммунальные расходы | I17: =Ввод!$M$12 -> руб | L17: =SUM(N17:R17) -> -6350000 | N17: =SUMIF($T$4:$EI$4,N$4,$T17:$EI17) -> -446000 | O17: =SUMIF($T$4:$EI$4,O$4,$T17:$EI17) -> -1044000 | P17: =SUMIF($T$4:$EI$4,P$4,$T17:$EI17) -> -1332000 | Q17: =SUMIF($T$4:$EI$4,Q$4,$T17:$EI17) -> -1620000 | R17: =SUMIF($T$4:$EI$4,R$4,$T17:$EI17) -> -1908000 | T17: =Расчет!V38 -> 0 | U17: =Расчет!W38 -> 0 | V17: =Расчет!X38 -> 0 | W17: =Расчет!Y38 -> 0 | X17: =Расчет!Z38 -> 0 | Y17: =Расчет!AA38 -> -50000 | Z17: =Расчет!AB38 -> -55000 | AA17: =Расчет!AC38 -> -60000 | ... CA17: =Расчет!CC38 -> -170000
D19: Валовая прибыль | I19: =Ввод!$M$12 -> руб | L19: =SUM(N19:R19) -> 368300000 | N19: =SUMIF($T$4:$EI$4,N$4,$T19:$EI19) -> 25868000 | O19: =SUMIF($T$4:$EI$4,O$4,$T19:$EI19) -> 60552000 | P19: =SUMIF($T$4:$EI$4,P$4,$T19:$EI19) -> 77256000 | Q19: =SUMIF($T$4:$EI$4,Q$4,$T19:$EI19) -> 93960000 | R19: =SUMIF($T$4:$EI$4,R$4,$T19:$EI19) -> 110664000 | T19: =T11+T13 -> 0 | U19: =U11+U13 -> 0 | V19: =V11+V13 -> 0 | W19: =W11+W13 -> 0 | X19: =X11+X13 -> 0 | Y19: =Y11+Y13 -> 2900000 | Z19: =Z11+Z13 -> 3190000 | AA19: =AA11+AA13 -> 3480000 | ... CA19: =CA11+CA13 -> 9860000
D20: Валовая маржа, % от выручки | I20: % | L20: =IFERROR(L19/L11,0) -> 0.58 | N20: =IFERROR(N19/N11,0) -> 0.58 | O20: =IFERROR(O19/O11,0) -> 0.58 | P20: =IFERROR(P19/P11,0) -> 0.58 | Q20: =IFERROR(Q19/Q11,0) -> 0.58 | R20: =IFERROR(R19/R11,0) -> 0.58 | T20: =IFERROR(T19/T11,0) -> 0 | U20: =IFERROR(U19/U11,0) -> 0 | V20: =IFERROR(V19/V11,0) -> 0 | W20: =IFERROR(W19/W11,0) -> 0 | X20: =IFERROR(X19/X11,0) -> 0 | Y20: =IFERROR(Y19/Y11,0) -> 0.58 | Z20: =IFERROR(Z19/Z11,0) -> 0.58 | AA20: =IFERROR(AA19/AA11,0) -> 0.58 | ... CA20: =IFERROR(CA19/CA11,0) -> 0.58
D22: Коммерческие затраты | I22: =Ввод!$M$12 -> руб | L22: =SUM(N22:R22) -> -20955000 | N22: =SUMIF($T$4:$EI$4,N$4,$T22:$EI22) -> -1471800 | O22: =SUMIF($T$4:$EI$4,O$4,$T22:$EI22) -> -3445200 | P22: =SUMIF($T$4:$EI$4,P$4,$T22:$EI22) -> -4395600 | Q22: =SUMIF($T$4:$EI$4,Q$4,$T22:$EI22) -> -5346000 | R22: =SUMIF($T$4:$EI$4,R$4,$T22:$EI22) -> -6296400 | T22: =Расчет!V55 -> 0 | U22: =Расчет!W55 -> 0 | V22: =Расчет!X55 -> 0 | W22: =Расчет!Y55 -> 0 | X22: =Расчет!Z55 -> 0 | Y22: =Расчет!AA55 -> -165000 | Z22: =Расчет!AB55 -> -181500 | AA22: =Расчет!AC55 -> -198000 | ... CA22: =Расчет!CC55 -> -561000
D23: =Расчет!D51 -> Реклама | I23: =Ввод!$M$12 -> руб | L23: =SUM(N23:R23) -> -6350000 | N23: =SUMIF($T$4:$EI$4,N$4,$T23:$EI23) -> -446000 | O23: =SUMIF($T$4:$EI$4,O$4,$T23:$EI23) -> -1044000 | P23: =SUMIF($T$4:$EI$4,P$4,$T23:$EI23) -> -1332000 | Q23: =SUMIF($T$4:$EI$4,Q$4,$T23:$EI23) -> -1620000 | R23: =SUMIF($T$4:$EI$4,R$4,$T23:$EI23) -> -1908000 | T23: =Расчет!V51 -> 0 | U23: =Расчет!W51 -> 0 | V23: =Расчет!X51 -> 0 | W23: =Расчет!Y51 -> 0 | X23: =Расчет!Z51 -> 0 | Y23: =Расчет!AA51 -> -50000 | Z23: =Расчет!AB51 -> -55000 | AA23: =Расчет!AC51 -> -60000 | ... CA23: =Расчет!CC51 -> -170000
D24: =Расчет!D52 -> Упаковка и маркировка | I24: =Ввод!$M$12 -> руб | L24: =SUM(N24:R24) -> -6350000 | N24: =SUMIF($T$4:$EI$4,N$4,$T24:$EI24) -> -446000 | O24: =SUMIF($T$4:$EI$4,O$4,$T24:$EI24) -> -1044000 | P24: =SUMIF($T$4:$EI$4,P$4,$T24:$EI24) -> -1332000 | Q24: =SUMIF($T$4:$EI$4,Q$4,$T24:$EI24) -> -1620000 | R24: =SUMIF($T$4:$EI$4,R$4,$T24:$EI24) -> -1908000 | T24: =Расчет!V52 -> 0 | U24: =Расчет!W52 -> 0 | V24: =Расчет!X52 -> 0 | W24: =Расчет!Y52 -> 0 | X24: =Расчет!Z52 -> 0 | Y24: =Расчет!AA52 -> -50000 | Z24: =Расчет!AB52 -> -55000 | AA24: =Расчет!AC52 -> -60000 | ... CA24: =Расчет!CC52 -> -170000
D25: =Расчет!D53 -> ГСМ | I25: =Ввод!$M$12 -> руб | L25: =SUM(N25:R25) -> -6350000 | N25: =SUMIF($T$4:$EI$4,N$4,$T25:$EI25) -> -446000 | O25: =SUMIF($T$4:$EI$4,O$4,$T25:$EI25) -> -1044000 | P25: =SUMIF($T$4:$EI$4,P$4,$T25:$EI25) -> -1332000 | Q25: =SUMIF($T$4:$EI$4,Q$4,$T25:$EI25) -> -1620000 | R25: =SUMIF($T$4:$EI$4,R$4,$T25:$EI25) -> -1908000 | T25: =Расчет!V53 -> 0 | U25: =Расчет!W53 -> 0 | V25: =Расчет!X53 -> 0 | W25: =Расчет!Y53 -> 0 | X25: =Расчет!Z53 -> 0 | Y25: =Расчет!AA53 -> -50000 | Z25: =Расчет!AB53 -> -55000 | AA25: =Расчет!AC53 -> -60000 | ... CA25: =Расчет!CC53 -> -170000
D26: =Расчет!D54 -> Расходы на транспортировку | I26: =Ввод!$M$12 -> руб | L26: =SUM(N26:R26) -> -1905000 | N26: =SUMIF($T$4:$EI$4,N$4,$T26:$EI26) -> -133800 | O26: =SUMIF($T$4:$EI$4,O$4,$T26:$EI26) -> -313200 | P26: =SUMIF($T$4:$EI$4,P$4,$T26:$EI26) -> -399600 | Q26: =SUMIF($T$4:$EI$4,Q$4,$T26:$EI26) -> -486000 | R26: =SUMIF($T$4:$EI$4,R$4,$T26:$EI26) -> -572400 | T26: =Расчет!V54 -> 0 | U26: =Расчет!W54 -> 0 | V26: =Расчет!X54 -> 0 | W26: =Расчет!Y54 -> 0 | X26: =Расчет!Z54 -> 0 | Y26: =Расчет!AA54 -> -15000 | Z26: =Расчет!AB54 -> -16500 | AA26: =Расчет!AC54 -> -18000 | ... CA26: =Расчет!CC54 -> -51000
D28: Общие и административные затраты | I28: =Ввод!$M$12 -> руб | L28: =SUM(N28:R28) -> -28800000 | N28: =SUMIF($T$4:$EI$4,N$4,$T28:$EI28) -> -4800000 | O28: =SUMIF($T$4:$EI$4,O$4,$T28:$EI28) -> -6000000 | P28: =SUMIF($T$4:$EI$4,P$4,$T28:$EI28) -> -6000000 | Q28: =SUMIF($T$4:$EI$4,Q$4,$T28:$EI28) -> -6000000 | R28: =SUMIF($T$4:$EI$4,R$4,$T28:$EI28) -> -6000000 | T28: =Расчет!V69 -> -260000 | U28: =Расчет!W69 -> -260000 | V28: =Расчет!X69 -> -260000 | W28: =Расчет!Y69 -> -260000 | X28: =Расчет!Z69 -> -260000 | Y28: =Расчет!AA69 -> -500000 | Z28: =Расчет!AB69 -> -500000 | AA28: =Расчет!AC69 -> -500000 | ... CA28: =Расчет!CC69 -> -500000
D29: =Расчет!D65 -> Расходы на управление | I29: =Ввод!$M$12 -> руб | L29: =SUM(N29:R29) -> -6000000 | N29: =SUMIF($T$4:$EI$4,N$4,$T29:$EI29) -> -1200000 | O29: =SUMIF($T$4:$EI$4,O$4,$T29:$EI29) -> -1200000 | P29: =SUMIF($T$4:$EI$4,P$4,$T29:$EI29) -> -1200000 | Q29: =SUMIF($T$4:$EI$4,Q$4,$T29:$EI29) -> -1200000 | R29: =SUMIF($T$4:$EI$4,R$4,$T29:$EI29) -> -1200000 | T29: =Расчет!V65 -> -100000 | U29: =Расчет!W65 -> -100000 | V29: =Расчет!X65 -> -100000 | W29: =Расчет!Y65 -> -100000 | X29: =Расчет!Z65 -> -100000 | Y29: =Расчет!AA65 -> -100000 | Z29: =Расчет!AB65 -> -100000 | AA29: =Расчет!AC65 -> -100000 | ... CA29: =Расчет!CC65 -> -100000
D30: =Расчет!D66 -> Содержание имущества | I30: =Ввод!$M$12 -> руб | L30: =SUM(N30:R30) -> -5550000 | N30: =SUMIF($T$4:$EI$4,N$4,$T30:$EI30) -> -750000 | O30: =SUMIF($T$4:$EI$4,O$4,$T30:$EI30) -> -1200000 | P30: =SUMIF($T$4:$EI$4,P$4,$T30:$EI30) -> -1200000 | Q30: =SUMIF($T$4:$EI$4,Q$4,$T30:$EI30) -> -1200000 | R30: =SUMIF($T$4:$EI$4,R$4,$T30:$EI30) -> -1200000 | T30: =Расчет!V66 -> -10000 | U30: =Расчет!W66 -> -10000 | V30: =Расчет!X66 -> -10000 | W30: =Расчет!Y66 -> -10000 | X30: =Расчет!Z66 -> -10000 | Y30: =Расчет!AA66 -> -100000 | Z30: =Расчет!AB66 -> -100000 | AA30: =Расчет!AC66 -> -100000 | ... CA30: =Расчет!CC66 -> -100000
D31: =Расчет!D67 -> Связь, IT и офисные расходы | I31: =Ввод!$M$12 -> руб | L31: =SUM(N31:R31) -> -5750000 | N31: =SUMIF($T$4:$EI$4,N$4,$T31:$EI31) -> -950000 | O31: =SUMIF($T$4:$EI$4,O$4,$T31:$EI31) -> -1200000 | P31: =SUMIF($T$4:$EI$4,P$4,$T31:$EI31) -> -1200000 | Q31: =SUMIF($T$4:$EI$4,Q$4,$T31:$EI31) -> -1200000 | R31: =SUMIF($T$4:$EI$4,R$4,$T31:$EI31) -> -1200000 | T31: =Расчет!V67 -> -50000 | U31: =Расчет!W67 -> -50000 | V31: =Расчет!X67 -> -50000 | W31: =Расчет!Y67 -> -50000 | X31: =Расчет!Z67 -> -50000 | Y31: =Расчет!AA67 -> -100000 | Z31: =Расчет!AB67 -> -100000 | AA31: =Расчет!AC67 -> -100000 | ... CA31: =Расчет!CC67 -> -100000
D32: =Расчет!D68 -> Налоги, сборы, прочие расходы | I32: =Ввод!$M$12 -> руб | L32: =SUM(N32:R32) -> -11500000 | N32: =SUMIF($T$4:$EI$4,N$4,$T32:$EI32) -> -1900000 | O32: =SUMIF($T$4:$EI$4,O$4,$T32:$EI32) -> -2400000 | P32: =SUMIF($T$4:$EI$4,P$4,$T32:$EI32) -> -2400000 | Q32: =SUMIF($T$4:$EI$4,Q$4,$T32:$EI32) -> -2400000 | R32: =SUMIF($T$4:$EI$4,R$4,$T32:$EI32) -> -2400000 | T32: =Расчет!V68 -> -100000 | U32: =Расчет!W68 -> -100000 | V32: =Расчет!X68 -> -100000 | W32: =Расчет!Y68 -> -100000 | X32: =Расчет!Z68 -> -100000 | Y32: =Расчет!AA68 -> -200000 | Z32: =Расчет!AB68 -> -200000 | AA32: =Расчет!AC68 -> -200000 | ... CA32: =Расчет!CC68 -> -200000
D34: Оплата труда | I34: =Ввод!$M$12 -> руб | L34: =SUM(N34:R34) -> -145740000 | N34: =SUMIF($T$4:$EI$4,N$4,$T34:$EI34) -> -20940000 | O34: =SUMIF($T$4:$EI$4,O$4,$T34:$EI34) -> -31200000 | P34: =SUMIF($T$4:$EI$4,P$4,$T34:$EI34) -> -31200000 | Q34: =SUMIF($T$4:$EI$4,Q$4,$T34:$EI34) -> -31200000 | R34: =SUMIF($T$4:$EI$4,R$4,$T34:$EI34) -> -31200000 | T34: =Расчет!V141 -> -700000 | U34: =Расчет!W141 -> -700000 | V34: =Расчет!X141 -> -700000 | W34: =Расчет!Y141 -> -700000 | X34: =Расчет!Z141 -> -1830000 | Y34: =Расчет!AA141 -> -1830000 | Z34: =Расчет!AB141 -> -1830000 | AA34: =Расчет!AC141 -> -2250000 | ... CA34: =Расчет!CC141 -> -2600000
D35: =Расчет!D115 -> Производство | I35: =Ввод!$M$12 -> руб | L35: =SUM(N35:R35) -> -54180000 | N35: =SUMIF($T$4:$EI$4,N$4,$T35:$EI35) -> -6660000 | O35: =SUMIF($T$4:$EI$4,O$4,$T35:$EI35) -> -11880000 | P35: =SUMIF($T$4:$EI$4,P$4,$T35:$EI35) -> -11880000 | Q35: =SUMIF($T$4:$EI$4,Q$4,$T35:$EI35) -> -11880000 | R35: =SUMIF($T$4:$EI$4,R$4,$T35:$EI35) -> -11880000 | T35: =Расчет!V122 -> 0 | U35: =Расчет!W122 -> 0 | V35: =Расчет!X122 -> 0 | W35: =Расчет!Y122 -> 0 | X35: =Расчет!Z122 -> -570000 | Y35: =Расчет!AA122 -> -570000 | Z35: =Расчет!AB122 -> -570000 | AA35: =Расчет!AC122 -> -990000 | ... CA35: =Расчет!CC122 -> -990000
D36: =Расчет!D124 -> Логистика | I36: =Ввод!$M$12 -> руб | L36: =SUM(N36:R36) -> -49560000 | N36: =SUMIF($T$4:$EI$4,N$4,$T36:$EI36) -> -5880000 | O36: =SUMIF($T$4:$EI$4,O$4,$T36:$EI36) -> -10920000 | P36: =SUMIF($T$4:$EI$4,P$4,$T36:$EI36) -> -10920000 | Q36: =SUMIF($T$4:$EI$4,Q$4,$T36:$EI36) -> -10920000 | R36: =SUMIF($T$4:$EI$4,R$4,$T36:$EI36) -> -10920000 | T36: =Расчет!V129 -> 0 | U36: =Расчет!W129 -> 0 | V36: =Расчет!X129 -> 0 | W36: =Расчет!Y129 -> 0 | X36: =Расчет!Z129 -> -560000 | Y36: =Расчет!AA129 -> -560000 | Z36: =Расчет!AB129 -> -560000 | AA36: =Расчет!AC129 -> -560000 | ... CA36: =Расчет!CC129 -> -910000
D37: =Расчет!D131 -> Администрация | I37: =Ввод!$M$12 -> руб | L37: =SUM(N37:R37) -> -42000000 | N37: =SUMIF($T$4:$EI$4,N$4,$T37:$EI37) -> -8400000 | O37: =SUMIF($T$4:$EI$4,O$4,$T37:$EI37) -> -8400000 | P37: =SUMIF($T$4:$EI$4,P$4,$T37:$EI37) -> -8400000 | Q37: =SUMIF($T$4:$EI$4,Q$4,$T37:$EI37) -> -8400000 | R37: =SUMIF($T$4:$EI$4,R$4,$T37:$EI37) -> -8400000 | T37: =Расчет!V139 -> -700000 | U37: =Расчет!W139 -> -700000 | V37: =Расчет!X139 -> -700000 | W37: =Расчет!Y139 -> -700000 | X37: =Расчет!Z139 -> -700000 | Y37: =Расчет!AA139 -> -700000 | Z37: =Расчет!AB139 -> -700000 | AA37: =Расчет!AC139 -> -700000 | ... CA37: =Расчет!CC139 -> -700000
D39: EBITDA | I39: =Ввод!$M$12 -> руб | L39: =SUM(N39:R39) -> 172805000 | N39: =SUMIF($T$4:$EI$4,N$4,$T39:$EI39) -> -1343800 | O39: =SUMIF($T$4:$EI$4,O$4,$T39:$EI39) -> 19906800 | P39: =SUMIF($T$4:$EI$4,P$4,$T39:$EI39) -> 35660400 | Q39: =SUMIF($T$4:$EI$4,Q$4,$T39:$EI39) -> 51414000 | R39: =SUMIF($T$4:$EI$4,R$4,$T39:$EI39) -> 67167600 | T39: =T19+T22+T28+T34 -> -960000 | U39: =U19+U22+U28+U34 -> -960000 | V39: =V19+V22+V28+V34 -> -960000 | W39: =W19+W22+W28+W34 -> -960000 | X39: =X19+X22+X28+X34 -> -2090000 | Y39: =Y19+Y22+Y28+Y34 -> 405000 | Z39: =Z19+Z22+Z28+Z34 -> 678500 | AA39: =AA19+AA22+AA28+AA34 -> 532000 | ... CA39: =CA19+CA22+CA28+CA34 -> 6199000
D40: EBITDA, % от выручки | I40: % | L40: =IFERROR(L39/L11,0) -> 0.27213386 | N40: =IFERROR(N39/N11,0) -> -0.030130045 | O40: =IFERROR(O39/O11,0) -> 0.19067816 | P40: =IFERROR(P39/P11,0) -> 0.26772072 | Q40: =IFERROR(Q39/Q11,0) -> 0.31737037 | R40: =IFERROR(R39/R11,0) -> 0.35203145 | T40: =IFERROR(T39/T11,0) -> 0 | U40: =IFERROR(U39/U11,0) -> 0 | V40: =IFERROR(V39/V11,0) -> 0 | W40: =IFERROR(W39/W11,0) -> 0 | X40: =IFERROR(X39/X11,0) -> 0 | Y40: =IFERROR(Y39/Y11,0) -> 0.081 | Z40: =IFERROR(Z39/Z11,0) -> 0.12336364 | AA40: =IFERROR(AA39/AA11,0) -> 0.088666667 | ... CA40: =IFERROR(CA39/CA11,0) -> 0.36464706
D42: Амортизация | I42: =Ввод!$M$12 -> руб | L42: =SUM(N42:R42) -> -26195355 | N42: =SUMIF($T$4:$EI$4,N$4,$T42:$EI42) -> -3244535.5 | O42: =SUMIF($T$4:$EI$4,O$4,$T42:$EI42) -> -5737704.9 | P42: =SUMIF($T$4:$EI$4,P$4,$T42:$EI42) -> -5737704.9 | Q42: =SUMIF($T$4:$EI$4,Q$4,$T42:$EI42) -> -5737704.9 | R42: =SUMIF($T$4:$EI$4,R$4,$T42:$EI42) -> -5737704.9 | T42: =Расчет!V193 -> 0 | U42: =Расчет!W193 -> 0 | V42: =Расчет!X193 -> 0 | W42: =Расчет!Y193 -> -68306.011 | X42: =Расчет!Z193 -> -239071.04 | Y42: =Расчет!AA193 -> -239071.04 | Z42: =Расчет!AB193 -> -307377.05 | AA42: =Расчет!AC193 -> -478142.08 | ... CA42: =Расчет!CC193 -> -478142.08
D43: Операционная прибыль (EBIT) | I43: =Ввод!$M$12 -> руб | L43: =SUM(N43:R43) -> 1.4660964e+08 | N43: =SUMIF($T$4:$EI$4,N$4,$T43:$EI43) -> -4588335.5 | O43: =SUMIF($T$4:$EI$4,O$4,$T43:$EI43) -> 14169095 | P43: =SUMIF($T$4:$EI$4,P$4,$T43:$EI43) -> 29922695 | Q43: =SUMIF($T$4:$EI$4,Q$4,$T43:$EI43) -> 45676295 | R43: =SUMIF($T$4:$EI$4,R$4,$T43:$EI43) -> 61429895 | T43: =T39+T42 -> -960000 | U43: =U39+U42 -> -960000 | V43: =V39+V42 -> -960000 | W43: =W39+W42 -> -1028306 | X43: =X39+X42 -> -2329071 | Y43: =Y39+Y42 -> 165928.96 | Z43: =Z39+Z42 -> 371122.95 | AA43: =AA39+AA42 -> 53857.923 | ... CA43: =CA39+CA42 -> 5720857.9
D44: Проценты к уплате | I44: =Ввод!$M$12 -> руб | L44: =SUM(N44:R44) -> -27332824 | N44: =SUMIF($T$4:$EI$4,N$4,$T44:$EI44) -> -8877394.1 | O44: =SUMIF($T$4:$EI$4,O$4,$T44:$EI44) -> -7457897 | P44: =SUMIF($T$4:$EI$4,P$4,$T44:$EI44) -> -5777366 | Q44: =SUMIF($T$4:$EI$4,Q$4,$T44:$EI44) -> -3787799.3 | R44: =SUMIF($T$4:$EI$4,R$4,$T44:$EI44) -> -1432367.8 | T44: =Расчет!V248 -> -788377.12 | U44: =Расчет!W248 -> -779952.6 | V44: =Расчет!X248 -> -771408.72 | W44: =Расчет!Y248 -> -762743.81 | X44: =Расчет!Z248 -> -753956.15 | Y44: =Расчет!AA248 -> -745043.99 | Z44: =Расчет!AB248 -> -736005.58 | AA44: =Расчет!AC248 -> -726839.12 | ... CA44: =Расчет!CC248 -> -19319.509
D45: Прибыль до налогообложения (EBT) | I45: =Ввод!$M$12 -> руб | L45: =SUM(N45:R45) -> 1.1927682e+08 | N45: =SUMIF($T$4:$EI$4,N$4,$T45:$EI45) -> -13465730 | O45: =SUMIF($T$4:$EI$4,O$4,$T45:$EI45) -> 6711198.1 | P45: =SUMIF($T$4:$EI$4,P$4,$T45:$EI45) -> 24145329 | Q45: =SUMIF($T$4:$EI$4,Q$4,$T45:$EI45) -> 41888496 | R45: =SUMIF($T$4:$EI$4,R$4,$T45:$EI45) -> 59997527 | T45: =T43+T44 -> -1748377.1 | U45: =U43+U44 -> -1739952.6 | V45: =V43+V44 -> -1731408.7 | W45: =W43+W44 -> -1791049.8 | X45: =X43+X44 -> -3083027.2 | Y45: =Y43+Y44 -> -579115.03 | Z45: =Z43+Z44 -> -364882.63 | AA45: =AA43+AA44 -> -672981.2 | ... CA45: =CA43+CA44 -> 5701538.4
D46: Налог на прибыль | I46: =Ввод!$M$12 -> руб | L46: =SUM(N46:R46) -> 33210629 | N46: =SUMIF($T$4:$EI$4,N$4,$T46:$EI46) -> 0 | O46: =SUMIF($T$4:$EI$4,O$4,$T46:$EI46) -> 1702790.5 | P46: =SUMIF($T$4:$EI$4,P$4,$T46:$EI46) -> 6036332.3 | Q46: =SUMIF($T$4:$EI$4,Q$4,$T46:$EI46) -> 10472124 | R46: =SUMIF($T$4:$EI$4,R$4,$T46:$EI46) -> 14999382 | T46: =Расчет!V239 -> 0 | U46: =Расчет!W239 -> 0 | V46: =Расчет!X239 -> 0 | W46: =Расчет!Y239 -> 0 | X46: =Расчет!Z239 -> 0 | Y46: =Расчет!AA239 -> 0 | Z46: =Расчет!AB239 -> 0 | AA46: =Расчет!AC239 -> 0 | ... CA46: =Расчет!CC239 -> 1425384.6
D48: Чистая прибыль | I48: =Ввод!$M$12 -> руб | L48: =SUM(N48:R48) -> 86066192 | N48: =SUMIF($T$4:$EI$4,N$4,$T48:$EI48) -> -13465730 | O48: =SUMIF($T$4:$EI$4,O$4,$T48:$EI48) -> 5008407.6 | P48: =SUMIF($T$4:$EI$4,P$4,$T48:$EI48) -> 18108997 | Q48: =SUMIF($T$4:$EI$4,Q$4,$T48:$EI48) -> 31416372 | R48: =SUMIF($T$4:$EI$4,R$4,$T48:$EI48) -> 44998145 | T48: =T45 - T46 -> -1748377.1 | U48: =U45 - U46 -> -1739952.6 | V48: =V45 - V46 -> -1731408.7 | W48: =W45 - W46 -> -1791049.8 | X48: =X45 - X46 -> -3083027.2 | Y48: =Y45 - Y46 -> -579115.03 | Z48: =Z45 - Z46 -> -364882.63 | AA48: =AA45 - AA46 -> -672981.2 | ... CA48: =CA45 - CA46 -> 4276153.8
D49: Чистая прибыль, % от выручки | I49: % | L49: =IFERROR(L48/L11,0) -> 0.13553731 | N49: =IFERROR(N48/N11,0) -> -0.30192219 | O49: =IFERROR(O48/O11,0) -> 0.047973253 | P49: =IFERROR(P48/P11,0) -> 0.13595343 | Q49: =IFERROR(Q48/Q11,0) -> 0.19392822 | R49: =IFERROR(R48/R11,0) -> 0.23583934 | T49: =IFERROR(T48/T11,0) -> 0 | U49: =IFERROR(U48/U11,0) -> 0 | V49: =IFERROR(V48/V11,0) -> 0 | W49: =IFERROR(W48/W11,0) -> 0 | X49: =IFERROR(X48/X11,0) -> 0 | Y49: =IFERROR(Y48/Y11,0) -> -0.11582301 | Z49: =IFERROR(Z48/Z11,0) -> -0.066342296 | AA49: =IFERROR(AA48/AA11,0) -> -0.11216353 | ... CA49: =IFERROR(CA48/CA11,0) -> 0.25153846
N50: =N45-N46 -> -13465730 | O50: =O45-O46 -> 5008407.6 | P50: =P45-P46 -> 18108997 | Q50: =Q45-Q46 -> 31416372 | R50: =R45-R46 -> 44998145
D51: Отчет о движении денежных средств - Cash Flow
D53: Денежные средства на начало периода | I53: =Ввод!$M$12 -> руб | N53: =SUMIFS($T53:$CA53,$T$4:$CA$4,N$4,$T$6:$CA$6,1) -> 0 | O53: =SUMIFS($T53:$CA53,$T$4:$CA$4,O$4,$T$6:$CA$6,1) -> 0 | P53: =SUMIFS($T53:$CA53,$T$4:$CA$4,P$4,$T$6:$CA$6,1) -> 2346280.8 | Q53: =SUMIFS($T53:$CA53,$T$4:$CA$4,Q$4,$T$6:$CA$6,1) -> 15355211 | R53: =SUMIFS($T53:$CA53,$T$4:$CA$4,R$4,$T$6:$CA$6,1) -> 39681950 | T53: =S76 -> 0 | U53: =T76 -> 0 | V53: =U76 -> 0 | W53: =V76 -> 0 | X53: =W76 -> 0 | Y53: =X76 -> 0 | Z53: =Y76 -> 0 | AA53: =Z76 -> 0 | ... CA53: =BZ76 -> 71846010
...

Sheet Результат
D5: Ввод | E5: Расчет | F5: Отчетность | G5: Результат
I8: Ед. изм | J8: Итого | L8: =Ввод!P8 -> 44197 | M8: =Ввод!Q8 -> 44562 | N8: =Ввод!R8 -> 44927 | O8: =Ввод!S8 -> 45292 | P8: =Ввод!T8 -> 45658
D9: Отчет о прибылях и убытках - P&L
D11: Выручка | I11: =Ввод!$M$12 -> руб | J11: =Отчетность!L11 -> 635000000 | L11: =Отчетность!N11 -> 44600000 | M11: =Отчетность!O11 -> 104400000 | N11: =Отчетность!P11 -> 133200000 | O11: =Отчетность!Q11 -> 162000000 | P11: =Отчетность!R11 -> 190800000
D12: Себестоимость | I12: =Ввод!$M$12 -> руб | J12: =Отчетность!L13 -> -266700000 | L12: =Отчетность!N13 -> -18732000 | M12: =Отчетность!O13 -> -43848000 | N12: =Отчетность!P13 -> -55944000 | O12: =Отчетность!Q13 -> -68040000 | P12: =Отчетность!R13 -> -80136000
D13: Валовая прибыль | I13: =Ввод!$M$12 -> руб | J13: =Отчетность!L19 -> 368300000 | L13: =Отчетность!N19 -> 25868000 | M13: =Отчетность!O19 -> 60552000 | N13: =Отчетность!P19 -> 77256000 | O13: =Отчетность!Q19 -> 93960000 | P13: =Отчетность!R19 -> 110664000
D14: Валовая маржа, % от выручки | I14: % | J14: =Отчетность!L20 -> 0.58 | L14: =Отчетность!N20 -> 0.58 | M14: =Отчетность!O20 -> 0.58 | N14: =Отчетность!P20 -> 0.58 | O14: =Отчетность!Q20 -> 0.58 | P14: =Отчетность!R20 -> 0.58
D16: Коммерческие затраты | I16: =Ввод!$M$12 -> руб | J16: =Отчетность!L22 -> -20955000 | L16: =Отчетность!N22 -> -1471800 | M16: =Отчетность!O22 -> -3445200 | N16: =Отчетность!P22 -> -4395600 | O16: =Отчетность!Q22 -> -5346000 | P16: =Отчетность!R22 -> -6296400
D17: Общие и административные затраты | I17: =Ввод!$M$12 -> руб | J17: =Отчетность!L28 -> -28800000 | L17: =Отчетность!N28 -> -4800000 | M17: =Отчетность!O28 -> -6000000 | N17: =Отчетность!P28 -> -6000000 | O17: =Отчетность!Q28 -> -6000000 | P17: =Отчетность!R28 -> -6000000
D18: Оплата труда | I18: =Ввод!$M$12 -> руб | J18: =Отчетность!L34 -> -145740000 | L18: =Отчетность!N34 -> -20940000 | M18: =Отчетность!O34 -> -31200000 | N18: =Отчетность!P34 -> -31200000 | O18: =Отчетность!Q34 -> -31200000 | P18: =Отчетность!R34 -> -31200000
D19: EBITDA | I19: =Ввод!$M$12 -> руб | J19: =Отчетность!L39 -> 172805000 | L19: =Отчетность!N39 -> -1343800 | M19: =Отчетность!O39 -> 19906800 | N19: =Отчетность!P39 -> 35660400 | O19: =Отчетность!Q39 -> 51414000 | P19: =Отчетность!R39 -> 67167600
D20: EBITDA, % от выручки | I20: % | J20: =Отчетность!L40 -> 0.27213386 | L20: =Отчетность!N40 -> -0.030130045 | M20: =Отчетность!O40 -> 0.19067816 | N20: =Отчетность!P40 -> 0.26772072 | O20: =Отчетность!Q40 -> 0.31737037 | P20: =Отчетность!R40 -> 0.35203145
D22: Амортизация | I22: =Ввод!$M$12 -> руб | J22: =Отчетность!L42 -> -26195355 | L22: =Отчетность!N42 -> -3244535.5 | M22: =Отчетность!O42 -> -5737704.9 | N22: =Отчетность!P42 -> -5737704.9 | O22: =Отчетность!Q42 -> -5737704.9 | P22: =Отчетность!R42 -> -5737704.9
D23: Операционная прибыль (EBIT) | I23: =Ввод!$M$12 -> руб | J23: =Отчетность!L43 -> 1.4660964e+08 | L23: =Отчетность!N43 -> -4588335.5 | M23: =Отчетность!O43 -> 14169095 | N23: =Отчетность!P43 -> 29922695 | O23: =Отчетность!Q43 -> 45676295 | P23: =Отчетность!R43 -> 61429895
D24: Проценты к уплате | I24: =Ввод!$M$12 -> руб | J24: =Отчетность!L44 -> -27332824 | L24: =Отчетность!N44 -> -8877394.1 | M24: =Отчетность!O44 -> -7457897 | N24: =Отчетность!P44 -> -5777366 | O24: =Отчетность!Q44 -> -3787799.3 | P24: =Отчетность!R44 -> -1432367.8
D25: Прибыль до налогообложения (EBT) | I25: =Ввод!$M$12 -> руб | J25: =Отчетность!L45 -> 1.1927682e+08 | L25: =Отчетность!N45 -> -13465730 | M25: =Отчетность!O45 -> 6711198.1 | N25: =Отчетность!P45 -> 24145329 | O25: =Отчетность!Q45 -> 41888496 | P25: =Отчетность!R45 -> 59997527
D26: Налог на прибыль | I26: =Ввод!$M$12 -> руб | J26: =Отчетность!L46 -> 33210629 | L26: =Отчетность!N46 -> 0 | M26: =Отчетность!O46 -> 1702790.5 | N26: =Отчетность!P46 -> 6036332.3 | O26: =Отчетность!Q46 -> 10472124 | P26: =Отчетность!R46 -> 14999382
D27: Чистая прибыль (убыток) | I27: =Ввод!$M$12 -> руб | J27: =Отчетность!L48 -> 86066192 | L27: =Отчетность!N48 -> -13465730 | M27: =Отчетность!O48 -> 5008407.6 | N27: =Отчетность!P48 -> 18108997 | O27: =Отчетность!Q48 -> 31416372 | P27: =Отчетность!R48 -> 44998145
D28: Чистая прибыль, % от выручки | I28: % | J28: =Отчетность!L49 -> 0.13553731 | L28: =Отчетность!N49 -> -0.30192219 | M28: =Отчетность!O49 -> 0.047973253 | N28: =Отчетность!P49 -> 0.13595343 | O28: =Отчетность!Q49 -> 0.19392822 | P28: =Отчетность!R49 -> 0.23583934
D31: Выручка и чистая прибыль
D49: Денежный поток
D51: Операционный поток | I51: =Ввод!$M$12 -> руб | J51: =Отчетность!L55 -> 1.3943082e+08 | L51: =Отчетность!N55 -> -1433180.8 | M51: =Отчетность!O55 -> 18185467 | N51: =Отчетность!P55 -> 29605525 | O51: =Отчетность!Q55 -> 40923334 | P51: =Отчетность!R55 -> 52149676
D53: Инвестиционный поток | I53: =Ввод!$M$12 -> руб | J53: =Отчетность!L63 -> -49180328 | L53: =Отчетность!N63 -> -49180328 | M53: =Отчетность!O63 -> 0 | N53: =Отчетность!P63 -> 0 | O53: =Отчетность!Q63 -> 0 | P53: =Отчетность!R63 -> 0
D54: Капитальные вложения | I54: =Ввод!$M$12 -> руб | J54: =Отчетность!L64 -> -49180328 | L54: =Отчетность!N64 -> -49180328 | M54: =Отчетность!O64 -> 0 | N54: =Отчетность!P64 -> 0 | O54: =Отчетность!Q64 -> 0 | P54: =Отчетность!R64 -> 0
D56: Финансовый поток | I56: =Ввод!$M$12 -> руб | J56: =Отчетность!L66 -> -15015462 | L56: =Отчетность!N66 -> 50613509 | M56: =Отчетность!O66 -> -15839186 | N56: =Отчетность!P66 -> -16596595 | O56: =Отчетность!Q66 -> -16596595 | P56: =Отчетность!R66 -> -16596595
D57: Привлечение долга | I57: =Ввод!$M$12 -> руб | J57: =Отчетность!L68 -> 56967512 | L57: =Отчетность!N68 -> 56210104 | M57: =Отчетность!O68 -> 757408.59 | N57: =Отчетность!P68 -> 0 | O57: =Отчетность!Q68 -> 0 | P57: =Отчетность!R68 -> 0
D58: Погашение долга | I58: =Ввод!$M$12 -> руб | J58: =Отчетность!L69 -> -55650150 | L58: =Отчетность!N69 -> -7719200.7 | M58: =Отчетность!O69 -> -9138697.9 | N58: =Отчетность!P69 -> -10819229 | O58: =Отчетность!Q69 -> -12808796 | P58: =Отчетность!R69 -> -15164227
D59: Выплата процентов | I59: =Ввод!$M$12 -> руб | J59: =Отчетность!L70 -> -27332824 | L59: =Отчетность!N70 -> -8877394.1 | M59: =Отчетность!O70 -> -7457897 | N59: =Отчетность!P70 -> -5777366 | O59: =Отчетность!Q70 -> -3787799.3 | P59: =Отчетность!R70 -> -1432367.8
D60: Капитал | I60: =Ввод!$M$12 -> руб | J60: =Отчетность!L72 -> 11000000 | L60: =Отчетность!N72 -> 11000000 | M60: =Отчетность!O72 -> 0 | N60: =Отчетность!P72 -> 0 | O60: =Отчетность!Q72 -> 0 | P60: =Отчетность!R72 -> 0
D62: Денежный поток | I62: =Ввод!$M$12 -> руб | J62: =Отчетность!L74 -> 75235031 | L62: =Отчетность!N74 -> 0 | M62: =Отчетность!O74 -> 2346280.8 | N62: =Отчетность!P74 -> 13008930 | O62: =Отчетность!Q74 -> 24326739 | P62: =Отчетность!R74 -> 35553081
D64: Денежные средства на конец периода | I64: =Ввод!$M$12 -> руб | L64: =Отчетность!N76 -> 0 | M64: =Отчетность!O76 -> 2346280.8 | N64: =Отчетность!P76 -> 15355211 | O64: =Отчетность!Q76 -> 39681950 | P64: =Отчетность!R76 -> 75235031
D66: Показатели эффективности
D68: Финансирование за счет капитала | I68: =Ввод!$M$12 -> руб | J68: =Отчетность!L80 -> -11000000 | L68: =Отчетность!N80 -> -11000000 | M68: =Отчетность!O80 -> 0 | N68: =Отчетность!P80 -> 0 | O68: =Отчетность!Q80 -> 0 | P68: =Отчетность!R80 -> 0
D69: Денежный поток актива | I69: =Ввод!$M$12 -> руб | J69: =Отчетность!L81 -> 75235031 | L69: =Отчетность!N81 -> 0 | M69: =Отчетность!O81 -> 2346280.8 | N69: =Отчетность!P81 -> 13008930 | O69: =Отчетность!Q81 -> 24326739 | P69: =Отчетность!R81 -> 35553081
D71: Чистый денежный поток (FCFE) | I71: =Ввод!$M$12 -> руб | J71: =Отчетность!L83 -> 64235031 | L71: =Отчетность!N83 -> -11000000 | M71: =Отчетность!O83 -> 2346280.8 | N71: =Отчетность!P83 -> 13008930 | O71: =Отчетность!Q83 -> 24326739 | P71: =Отчетность!R83 -> 35553081
D72: Накопленный денежный поток | I72: =Ввод!$M$12 -> руб | L72: =Отчетность!N84 -> -11000000 | M72: =Отчетность!O84 -> -8653719.2 | N72: =Отчетность!P84 -> 4355211.2 | O72: =Отчетность!Q84 -> 28681950 | P72: =Отчетность!R84 -> 64235031
D74: Внутренняя норма доходности (IRR) | I74: % | J74: =Отчетность!L86 -> 0.89190128
D75: Период окупаемости (PBP) | I75: лет | J75: =Отчетность!L87 -> 2.6666667
D78: Накопленный денежный поток (период окупаемости)
